2021-03-29 00:21:34,931 [DEBUG] /usr/local/lib/python3.7/site-packages/django/template/base.py:872 Exception while resolving variable 'build_absolute_uri' in template 'unknown'.
Traceback (most recent call last):
  File "/usr/local/lib/python3.7/site-packages/django/core/handlers/exception.py", line 34, in inner
    response = get_response(request)
  File "/usr/local/lib/python3.7/site-packages/django/core/handlers/base.py", line 100, in _get_response
    resolver_match = resolver.resolve(request.path_info)
  File "/usr/local/lib/python3.7/site-packages/django/urls/resolvers.py", line 567, in resolve
    raise Resolver404({'tried': tried, 'path': new_path})
django.urls.exceptions.Resolver404: {'tried': [[<URLResolver <module 'app.urls' from './app/urls.py'> (None:None) 'app/'>, <URLPattern 'login' [name='login_top']>], [<URLResolver <module 'app.urls' from './app/urls.py'> (None:None) 'app/'>, <URLPattern '' [name='index_top']>]], 'path': 'app/style.css'}

During handling of the above exception, another exception occurred:

Traceback (most recent call last):
  File "/usr/local/lib/python3.7/site-packages/django/template/base.py", line 858, in _resolve_lookup
    current = current()
  File "/usr/local/lib/python3.7/site-packages/django/http/request.py", line 195, in build_absolute_uri
    location = self._current_scheme_host + location
  File "/usr/local/lib/python3.7/site-packages/django/utils/functional.py", line 80, in __get__
    res = instance.__dict__[self.name] = self.func(instance)
  File "/usr/local/lib/python3.7/site-packages/django/http/request.py", line 205, in _current_scheme_host
    return '{}://{}'.format(self.scheme, self.get_host())
  File "/usr/local/lib/python3.7/site-packages/django/http/request.py", line 111, in get_host
    raise DisallowedHost(msg)
django.core.exceptions.DisallowedHost: Invalid HTTP_HOST header: 'krzmknt.com'. You may need to add 'krzmknt.com' to ALLOWED_HOSTS.
2021-03-29 00:21:35,626 [DEBUG] /usr/local/lib/python3.7/site-packages/django/template/base.py:872 Exception while resolving variable 'build_absolute_uri' in template 'unknown'.
Traceback (most recent call last):
  File "/usr/local/lib/python3.7/site-packages/django/core/handlers/exception.py", line 34, in inner
    response = get_response(request)
  File "/usr/local/lib/python3.7/site-packages/django/core/handlers/base.py", line 100, in _get_response
    resolver_match = resolver.resolve(request.path_info)
  File "/usr/local/lib/python3.7/site-packages/django/urls/resolvers.py", line 567, in resolve
    raise Resolver404({'tried': tried, 'path': new_path})
django.urls.exceptions.Resolver404: {'tried': [[<URLResolver <module 'app.urls' from './app/urls.py'> (None:None) 'app/'>, <URLPattern 'login' [name='login_top']>], [<URLResolver <module 'app.urls' from './app/urls.py'> (None:None) 'app/'>, <URLPattern '' [name='index_top']>]], 'path': 'app/style.css'}

During handling of the above exception, another exception occurred:

Traceback (most recent call last):
  File "/usr/local/lib/python3.7/site-packages/django/template/base.py", line 858, in _resolve_lookup
    current = current()
  File "/usr/local/lib/python3.7/site-packages/django/http/request.py", line 195, in build_absolute_uri
    location = self._current_scheme_host + location
  File "/usr/local/lib/python3.7/site-packages/django/utils/functional.py", line 80, in __get__
    res = instance.__dict__[self.name] = self.func(instance)
  File "/usr/local/lib/python3.7/site-packages/django/http/request.py", line 205, in _current_scheme_host
    return '{}://{}'.format(self.scheme, self.get_host())
  File "/usr/local/lib/python3.7/site-packages/django/http/request.py", line 111, in get_host
    raise DisallowedHost(msg)
django.core.exceptions.DisallowedHost: Invalid HTTP_HOST header: 'krzmknt.com'. You may need to add 'krzmknt.com' to ALLOWED_HOSTS.
2021-03-29 00:21:36,721 [DEBUG] /usr/local/lib/python3.7/site-packages/django/template/base.py:872 Exception while resolving variable 'build_absolute_uri' in template 'unknown'.
Traceback (most recent call last):
  File "/usr/local/lib/python3.7/site-packages/django/core/handlers/exception.py", line 34, in inner
    response = get_response(request)
  File "/usr/local/lib/python3.7/site-packages/django/core/handlers/base.py", line 100, in _get_response
    resolver_match = resolver.resolve(request.path_info)
  File "/usr/local/lib/python3.7/site-packages/django/urls/resolvers.py", line 567, in resolve
    raise Resolver404({'tried': tried, 'path': new_path})
django.urls.exceptions.Resolver404: {'tried': [[<URLResolver <module 'app.urls' from './app/urls.py'> (None:None) 'app/'>, <URLPattern 'login' [name='login_top']>], [<URLResolver <module 'app.urls' from './app/urls.py'> (None:None) 'app/'>, <URLPattern '' [name='index_top']>]], 'path': 'app/style.css'}

During handling of the above exception, another exception occurred:

Traceback (most recent call last):
  File "/usr/local/lib/python3.7/site-packages/django/template/base.py", line 858, in _resolve_lookup
    current = current()
  File "/usr/local/lib/python3.7/site-packages/django/http/request.py", line 195, in build_absolute_uri
    location = self._current_scheme_host + location
  File "/usr/local/lib/python3.7/site-packages/django/utils/functional.py", line 80, in __get__
    res = instance.__dict__[self.name] = self.func(instance)
  File "/usr/local/lib/python3.7/site-packages/django/http/request.py", line 205, in _current_scheme_host
    return '{}://{}'.format(self.scheme, self.get_host())
  File "/usr/local/lib/python3.7/site-packages/django/http/request.py", line 111, in get_host
    raise DisallowedHost(msg)
django.core.exceptions.DisallowedHost: Invalid HTTP_HOST header: 'krzmknt.com'. You may need to add 'krzmknt.com' to ALLOWED_HOSTS.
2021-03-29 00:21:36,793 [DEBUG] /usr/local/lib/python3.7/site-packages/django/template/base.py:872 Exception while resolving variable 'build_absolute_uri' in template 'unknown'.
Traceback (most recent call last):
  File "/usr/local/lib/python3.7/site-packages/django/core/handlers/exception.py", line 34, in inner
    response = get_response(request)
  File "/usr/local/lib/python3.7/site-packages/django/core/handlers/base.py", line 100, in _get_response
    resolver_match = resolver.resolve(request.path_info)
  File "/usr/local/lib/python3.7/site-packages/django/urls/resolvers.py", line 567, in resolve
    raise Resolver404({'tried': tried, 'path': new_path})
django.urls.exceptions.Resolver404: {'tried': [[<URLResolver <module 'app.urls' from './app/urls.py'> (None:None) 'app/'>, <URLPattern 'login' [name='login_top']>], [<URLResolver <module 'app.urls' from './app/urls.py'> (None:None) 'app/'>, <URLPattern '' [name='index_top']>]], 'path': 'app/style.css'}

During handling of the above exception, another exception occurred:

Traceback (most recent call last):
  File "/usr/local/lib/python3.7/site-packages/django/template/base.py", line 858, in _resolve_lookup
    current = current()
  File "/usr/local/lib/python3.7/site-packages/django/http/request.py", line 195, in build_absolute_uri
    location = self._current_scheme_host + location
  File "/usr/local/lib/python3.7/site-packages/django/utils/functional.py", line 80, in __get__
    res = instance.__dict__[self.name] = self.func(instance)
  File "/usr/local/lib/python3.7/site-packages/django/http/request.py", line 205, in _current_scheme_host
    return '{}://{}'.format(self.scheme, self.get_host())
  File "/usr/local/lib/python3.7/site-packages/django/http/request.py", line 111, in get_host
    raise DisallowedHost(msg)
django.core.exceptions.DisallowedHost: Invalid HTTP_HOST header: 'krzmknt.com'. You may need to add 'krzmknt.com' to ALLOWED_HOSTS.
